<?xml version="1.0" ?>
<!-- =================================================================================== -->
<!-- |    This document was autogenerated by xacro from ubiquitous_display.urdf.xacro  | -->
<!-- |    EDITING THIS FILE BY HAND IS NOT RECOMMENDED                                 | -->
<!-- =================================================================================== -->
<robot name="ubiquitous_didsplay" xmlns:controller="http://playerstage.sourceforge.net/gazebo/xmlschema/#controller" xmlns:interface="http://playerstage.sourceforge.net/gazebo/xmlschema/#interface" xmlns:sensor="http://playerstage.sourceforge.net/gazebo/xmlschema/#sensor" xmlns:xacro="http://www.ros.org/wiki/xacro">
  <!-- Definition of colors -->
  <material name="black">
    <color rgba="0 0 0 1"/>
  </material>
  <material name="white">
    <color rgba="1 1 1 1"/>
  </material>
  <link name="bottom_pillars_link">
    <visual>
      <geometry>
        <cylinder length="0.1" radius="0.01"/>
      </geometry>
      <origin xyz="0.21 0.06 0.05"/>
      <material name="black"/>
    </visual>
    <visual>
      <geometry>
        <cylinder length="0.1" radius="0.01"/>
      </geometry>
      <origin xyz="-0.21 0.06 0.05"/>
      <material name="black"/>
    </visual>
    <visual>
      <geometry>
        <cylinder length="0.1" radius="0.01"/>
      </geometry>
      <origin xyz="0.21 -0.06 0.05"/>
      <material name="black"/>
    </visual>
    <visual>
      <geometry>
        <cylinder length="0.1" radius="0.01"/>
      </geometry>
      <origin xyz="-0.21 -0.06 0.05"/>
      <material name="black"/>
    </visual>
  </link>
  <link name="bottom_plate_link">
    <visual>
      <geometry>
        <box size="0.5 0.2 0.004"/>
      </geometry>
      <origin xyz="0 0 -0.002"/>
      <material name="white"/>
    </visual>
  </link>
  <joint name="bottom_pillars_to_bottom_plate_joint" type="fixed">
    <parent link="bottom_pillars_link"/>
    <child link="bottom_plate_link"/>
    <origin xyz="0 0 0.1"/>
  </joint>
  <link name="middle_pillars_link">
    <visual>
      <geometry>
        <cylinder length="0.157" radius="0.01"/>
      </geometry>
      <origin xyz="0.21 0.06 0.0785"/>
      <material name="black"/>
    </visual>
    <visual>
      <geometry>
        <cylinder length="0.157" radius="0.01"/>
      </geometry>
      <origin xyz="-0.21 0.06 0.0785"/>
      <material name="black"/>
    </visual>
    <visual>
      <geometry>
        <cylinder length="0.157" radius="0.01"/>
      </geometry>
      <origin xyz="0.21 -0.06 0.0785"/>
      <material name="black"/>
    </visual>
    <visual>
      <geometry>
        <cylinder length="0.157" radius="0.01"/>
      </geometry>
      <origin xyz="-0.21 -0.06 0.0785"/>
      <material name="black"/>
    </visual>
  </link>
  <link name="middle_plate_link">
    <visual>
      <geometry>
        <box size="0.5 0.2 0.004"/>
      </geometry>
      <origin xyz="0 0 -0.002"/>
      <material name="white"/>
    </visual>
  </link>
  <joint name="middle_pillars_to_middle_plate_joint" type="fixed">
    <parent link="middle_pillars_link"/>
    <child link="middle_plate_link"/>
    <origin xyz="0 0 0.157"/>
  </joint>
  <joint name="bottom_plate_to_middle_pillars_joint" type="fixed">
    <parent link="bottom_plate_link"/>
    <child link="middle_pillars_link"/>
  </joint>
  <link name="top_pillars_link">
    <visual>
      <geometry>
        <cylinder length="0.435" radius="0.01"/>
      </geometry>
      <origin xyz="0.21 0.06 0.2175"/>
      <material name="black"/>
    </visual>
    <visual>
      <geometry>
        <cylinder length="0.435" radius="0.01"/>
      </geometry>
      <origin xyz="-0.21 0.06 0.2175"/>
      <material name="black"/>
    </visual>
    <visual>
      <geometry>
        <cylinder length="0.435" radius="0.01"/>
      </geometry>
      <origin xyz="0.21 -0.06 0.2175"/>
      <material name="black"/>
    </visual>
    <visual>
      <geometry>
        <cylinder length="0.435" radius="0.01"/>
      </geometry>
      <origin xyz="-0.21 -0.06 0.2175"/>
      <material name="black"/>
    </visual>
  </link>
  <link name="top_plate_link">
    <visual>
      <geometry>
        <box size="0.5 0.2 0.004"/>
      </geometry>
      <origin xyz="0 0 -0.002"/>
      <material name="white"/>
    </visual>
  </link>
  <joint name="top_pillars_to_top_plate_joint" type="fixed">
    <parent link="top_pillars_link"/>
    <child link="top_plate_link"/>
    <origin xyz="0 0 0.435"/>
  </joint>
  <joint name="middle_plate_to_top_pillars_joint" type="fixed">
    <parent link="middle_plate_link"/>
    <child link="top_pillars_link"/>
  </joint>
  <link name="front_laser_adjuster_link">
    <visual>
      <geometry>
        <box size="0.18 0.02 0.02"/>
      </geometry>
      <origin xyz="-0.09 0.025 0.01"/>
      <material name="white"/>
    </visual>
    <visual>
      <geometry>
        <box size="0.18 0.02 0.02"/>
      </geometry>
      <origin xyz="-0.09 -0.025 0.01"/>
      <material name="white"/>
    </visual>
  </link>
  <joint name="front_laser_adjuster_joint" type="fixed">
    <origin rpy="0 0 0" xyz="0.3 0 0"/>
    <parent link="bottom_plate_link"/>
    <child link="front_laser_adjuster_link"/>
  </joint>
  <link name="rear_laser_adjuster_link">
    <visual>
      <geometry>
        <box size="0.18 0.02 0.02"/>
      </geometry>
      <origin xyz="-0.09 0.025 0.01"/>
      <material name="white"/>
    </visual>
    <visual>
      <geometry>
        <box size="0.18 0.02 0.02"/>
      </geometry>
      <origin xyz="-0.09 -0.025 0.01"/>
      <material name="white"/>
    </visual>
  </link>
  <joint name="rear_laser_adjuster_joint" type="fixed">
    <origin rpy="0 0 3.1415" xyz="-0.3 0 0"/>
    <parent link="bottom_plate_link"/>
    <child link="rear_laser_adjuster_link"/>
  </joint>
  <material name="red">
    <color rgba="0.7 0.0 0.7 1.0"/>
  </material>
  <material name="blue">
    <color rgba="0.0 0.7 0.7 1.0"/>
  </material>
  <material name="green">
    <color rgba="0.0 0.7 0.7 1.0"/>
  </material>
  <material name="gray">
    <color rgba="0.7 0.7 0.7 1.0"/>
  </material>
  <link name="ud_pt_base_link">
    </link>
  <link name="ud_pt_box_link">
    <visual>
      <origin rpy="0 0 0" xyz="0 0 0"/>
      <geometry>
        <box size="0.07 0.085 0.065"/>
      </geometry>
      <material name="gray"/>
    </visual>
  </link>
  <link name="ud_pt_plate_link">
    <visual>
      <origin rpy="0 0 0" xyz="-0.075 0 0"/>
      <geometry>
        <box size="0.35 0.095 0.003"/>
      </geometry>
      <material name="gray"/>
    </visual>
  </link>
  <link name="left_pt_pillars">
    <visual>
      <origin rpy="0 0 0" xyz="0 0 0"/>
      <geometry>
        <box size="0.01 0.05 0.20"/>
      </geometry>
      <material name="gray"/>
    </visual>
  </link>
  <link name="right_pt_pillars">
    <visual>
      <origin rpy="0 0 0" xyz="0 0 0"/>
      <geometry>
        <box size="0.01 0.05 0.20"/>
      </geometry>
      <material name="gray"/>
    </visual>
  </link>
  <link name="ud_pt_projector_link">
    <visual>
      <origin rpy="0 0 0" xyz="0.07 0.037 0"/>
      <geometry>
        <box size="0.24 0.17 0.07"/>
      </geometry>
      <material name="gray"/>
    </visual>
  </link>
  <joint name="ud_pt_base_joint" type="fixed">
    <parent link="ud_pt_base_link"/>
    <child link="ud_pt_box_link"/>
    <origin rpy="0 0 0" xyz="0 0 0"/>
  </joint>
  <!--name of pan_joint and tilt_joint depend pantilt.yaml-->
  <joint name="pan_joint" type="revolute">
    <parent link="ud_pt_box_link"/>
    <child link="ud_pt_plate_link"/>
    <origin rpy="0 0 0" xyz="0 0 0.0325"/>
    <axis xyz="0 0 1"/>
    <limit effort="1" lower="0" upper="2" velocity="1"/>
  </joint>
  <joint name="ud_pt_plate_link_to_left_pt_pillars" type="fixed">
    <parent link="ud_pt_plate_link"/>
    <child link="left_pt_pillars"/>
    <origin rpy="0 0 0" xyz="0.09 0 0.1"/>
  </joint>
  <joint name="ud_pt_plate_link_to_right_pt_pillars" type="fixed">
    <parent link="ud_pt_plate_link"/>
    <child link="right_pt_pillars"/>
    <origin rpy="0 0 0" xyz="-0.24 0 0.1"/>
  </joint>
  <joint name="tilt_joint" type="revolute">
    <parent link="ud_pt_plate_link"/>
    <child link="ud_pt_projector_link"/>
    <origin rpy="0 0 3.14" xyz="0 0 0.17"/>
    <axis xyz="1 0 0"/>
    <limit effort="1" lower="0" upper="2" velocity="1"/>
  </joint>
  <!--xacro:property name="" value="0.360" /-->
  <material name="Orange">
    <color rgba="1.0 0.4 0.0 1.0"/>
  </material>
  <material name="Grey">
    <color rgba="0.7 0.7 0.7 1.0"/>
  </material>
  <material name="DarkGrey">
    <color rgba="0.3 0.3 0.3 1.0"/>
  </material>
  <material name="White">
    <color rgba="1.0 1.0 1.0 1.0"/>
  </material>
  <material name="Black">
    <color rgba="0.0 0.0 0.0 1.0"/>
  </material>
  <material name="Red">
    <color rgba="1.0 0.0 0.0 1.0"/>
  </material>
  <material name="Green">
    <color rgba="0.0 1.0 0.0 1.0"/>
  </material>
  <material name="Blue">
    <color rgba="0.0 0.0 0.8 1.0"/>
  </material>
  <material name="LightGrey">
    <color rgba="0.82 0.82 0.82 1.0"/>
  </material>
  <gazebo>
    <plugin filename="libgazebo_ros_control.so" name="gazebo_ros_controller"/>
  </gazebo>
  <!-- Now we can start using the macros xacro:included above to define the actual youbot -->
  <!-- The first use of a macro.  This one was defined in base.urdf.xacro above.
       A macro like this will expand to a set of link and joint definitions, and to additional
       Gazebo-related extensions (sensor plugins, etc).  The macro takes an argument, name,
       that equals "base", and uses it to generate names for its component links and joints
       (e.g., base_link).  The xacro:included origin block is also an argument to the macro.  By convention,
       the origin block defines where the component is w.r.t its parent (in this case the parent
       is the world frame). For more, see http://www.ros.org/wiki/xacro -->
  <link name="ud_base_footprint"/>
  <joint name="ud_base_footprint_joint" type="fixed">
    <origin rpy="0 0 0" xyz="0 0 0.10"/>
    <parent link="ud_base_footprint"/>
    <child link="ud_base_link"/>
  </joint>
  <link name="ud_base_link">
    <inertial>
      <mass value="22.0"/>
      <origin xyz="0 0 0"/>
      <inertia ixx="5.652232699207" ixy="-0.009719934438" ixz="1.293988226423" iyy="5.669473158652" iyz="-0.007379583694" izz="3.683196351726"/>
    </inertial>
    <visual>
      <origin rpy="0 0 0" xyz="0 0 0"/>
      <geometry>
        <mesh filename="package://ubiquitous_display_description/meshes/base.dae"/>
      </geometry>
      <material name="DarkGrey"/>
    </visual>
    <collision>
      <origin rpy="0 0 0" xyz="0 0 0"/>
      <geometry>
        <!--<box size="${base_size_x} ${base_size_y} ${base_size_z}" />-->
        <mesh filename="package://ubiquitous_display_description/meshes/base_convex.dae"/>
      </geometry>
    </collision>
  </link>
  <!-- front left wheel -->
  <joint name="caster_joint_fl" type="continuous">
    <origin rpy="0 0 0" xyz="0.228 0.158 -0.034"/>
    <axis xyz="0 0 1"/>
    <limit effort="30" velocity="10"/>
    <dynamics damping="1.0" friction="1.0"/>
    <safety_controller k_velocity="10.0"/>
    <parent link="ud_base_link"/>
    <child link="caster_link_fl"/>
  </joint>
  <link name="caster_link_fl">
    <inertial>
      <mass value="0.1"/>
      <origin xyz="0 0 0"/>
      <inertia ixx="0.012411765597" ixy="-0.000711733678" ixz="0.00050272983" iyy="0.015218160428" iyz="-0.000004273467" izz="0.011763977943"/>
    </inertial>
  </link>
  <joint name="wheel_joint_fl" type="continuous">
    <axis xyz="0 1 0"/>
    <limit effort="30" velocity="10"/>
    <origin rpy="0 0 0" xyz="0.0 0.0 0.0"/>
    <parent link="caster_link_fl"/>
    <dynamics damping="1.0" friction="1.0"/>
    <safety_controller k_velocity="10.0"/>
    <child link="wheel_link_fl"/>
  </joint>
  <link name="wheel_link_fl">
    <inertial>
      <mass value="0.4"/>
      <origin xyz="0 0 0"/>
      <inertia ixx="0.012411765597" ixy="-0.000711733678" ixz="0.00050272983" iyy="0.015218160428" iyz="-0.000004273467" izz="0.011763977943"/>
    </inertial>
    <visual>
      <origin rpy="0 0 0" xyz="0 0 0"/>
      <!--<mesh filename="package://youbot_description/meshes/youbot_base/youbot_wheel.stl" />-->
      <geometry>
        <sphere radius="0.05"/>
      </geometry>
      <material name="Orange"/>
    </visual>
    <collision>
      <origin rpy="1.57079632679 0 0" xyz="0 0 0"/>
      <geometry>
        <cylinder length="0.05" radius="0.05"/>
      </geometry>
    </collision>
  </link>
  <!-- front right wheel -->
  <joint name="caster_joint_fr" type="continuous">
    <origin rpy="0 0 0" xyz="0.228 -0.158 -0.034"/>
    <axis xyz="0 0 1"/>
    <limit effort="30" velocity="10"/>
    <dynamics damping="1.0" friction="1.0"/>
    <safety_controller k_velocity="10.0"/>
    <parent link="ud_base_link"/>
    <child link="caster_link_fr"/>
  </joint>
  <link name="caster_link_fr">
    <inertial>
      <mass value="0.1"/>
      <origin xyz="0 0 0"/>
      <inertia ixx="0.012411765597" ixy="-0.000711733678" ixz="0.00050272983" iyy="0.015218160428" iyz="-0.000004273467" izz="0.011763977943"/>
    </inertial>
  </link>
  <joint name="wheel_joint_fr" type="continuous">
    <axis xyz="0 1 0"/>
    <limit effort="30" velocity="10"/>
    <dynamics damping="1.0" friction="1.0"/>
    <safety_controller k_velocity="10.0"/>
    <origin rpy="0 0 0" xyz="0.0 0.0 0.0"/>
    <parent link="caster_link_fr"/>
    <child link="wheel_link_fr"/>
  </joint>
  <link name="wheel_link_fr">
    <inertial>
      <mass value="0.4"/>
      <origin xyz="0 0 0"/>
      <inertia ixx="0.012411765597" ixy="-0.000711733678" ixz="0.00050272983" iyy="0.015218160428" iyz="-0.000004273467" izz="0.011763977943"/>
    </inertial>
    <visual>
      <origin rpy="0 0 0" xyz="0 0 0"/>
      <geometry>
        <!--<mesh filename="package://youbot_description/meshes/youbot_base/youbot_wheel.stl" />-->
        <sphere radius="0.05"/>
      </geometry>
      <material name="Orange"/>
    </visual>
    <collision>
      <origin rpy="1.57079632679 0 0" xyz="0 0 0"/>
      <geometry>
        <cylinder length="0.05" radius="0.05"/>
      </geometry>
    </collision>
  </link>
  <!-- back left wheel -->
  <joint name="caster_joint_bl" type="continuous">
    <origin rpy="0 0 0" xyz="-0.228 0.158 -0.034"/>
    <axis xyz="0 0 1"/>
    <limit effort="30" velocity="10"/>
    <dynamics damping="1.0" friction="1.0"/>
    <safety_controller k_velocity="10.0"/>
    <parent link="ud_base_link"/>
    <child link="caster_link_bl"/>
  </joint>
  <link name="caster_link_bl">
    <inertial>
      <mass value="0.1"/>
      <origin xyz="0 0 0"/>
      <inertia ixx="0.012411765597" ixy="-0.000711733678" ixz="0.00050272983" iyy="0.015218160428" iyz="-0.000004273467" izz="0.011763977943"/>
    </inertial>
  </link>
  <joint name="wheel_joint_bl" type="continuous">
    <axis xyz="0 1 0"/>
    <limit effort="10" velocity="10"/>
    <limit effort="30" velocity="10"/>
    <dynamics damping="1.0" friction="1.0"/>
    <safety_controller k_velocity="10.0"/>
    <origin rpy="0 0 0" xyz="0.0 0.0 0.0"/>
    <parent link="caster_link_bl"/>
    <child link="wheel_link_bl"/>
  </joint>
  <link name="wheel_link_bl">
    <inertial>
      <mass value="0.4"/>
      <origin xyz="0 0 0"/>
      <inertia ixx="0.012411765597" ixy="-0.000711733678" ixz="0.00050272983" iyy="0.015218160428" iyz="-0.000004273467" izz="0.011763977943"/>
    </inertial>
    <visual>
      <origin rpy="0 0 0" xyz="0 0 0"/>
      <geometry>
        <!--<mesh filename="package://youbot_description/meshes/youbot_base/youbot_wheel.stl" />-->
        <sphere radius="0.05"/>
      </geometry>
      <material name="Orange"/>
    </visual>
    <collision>
      <origin rpy="1.57079632679 0 0" xyz="0 0 0"/>
      <geometry>
        <cylinder length="0.05" radius="0.05"/>
      </geometry>
    </collision>
  </link>
  <!-- back right wheel -->
  <joint name="caster_joint_br" type="continuous">
    <origin rpy="0 0 0" xyz="-0.228 -0.158 -0.034"/>
    <axis xyz="0 0 1"/>
    <limit effort="30" velocity="10"/>
    <dynamics damping="1.0" friction="1.0"/>
    <safety_controller k_velocity="10.0"/>
    <parent link="ud_base_link"/>
    <child link="caster_link_br"/>
  </joint>
  <link name="caster_link_br">
    <inertial>
      <mass value="0.1"/>
      <origin xyz="0 0 0"/>
      <inertia ixx="0.012411765597" ixy="-0.000711733678" ixz="0.00050272983" iyy="0.015218160428" iyz="-0.000004273467" izz="0.011763977943"/>
    </inertial>
  </link>
  <joint name="wheel_joint_br" type="continuous">
    <axis xyz="0 1 0"/>
    <limit effort="30" velocity="10"/>
    <dynamics damping="1.0" friction="1.0"/>
    <safety_controller k_velocity="10.0"/>
    <origin rpy="0 0 0" xyz="0.0 0.0 0.0"/>
    <parent link="caster_link_br"/>
    <child link="wheel_link_br"/>
  </joint>
  <link name="wheel_link_br">
    <inertial>
      <mass value="0.4"/>
      <origin xyz="0 0 0"/>
      <inertia ixx="0.012411765597" ixy="-0.000711733678" ixz="0.00050272983" iyy="0.015218160428" iyz="-0.000004273467" izz="0.011763977943"/>
    </inertial>
    <visual>
      <origin rpy="0 0 0" xyz="0 0 0"/>
      <geometry>
        <!--<mesh filename="package://youbot_description/meshes/youbot_base/youbot_wheel.stl" />-->
        <sphere radius="0.05"/>
      </geometry>
      <material name="Orange"/>
    </visual>
    <collision>
      <origin rpy="1.57079632679 0 0" xyz="0 0 0"/>
      <geometry>
        <cylinder length="0.05" radius="0.05"/>
      </geometry>
    </collision>
  </link>
  <gazebo reference="youbot_base">
    <material value="youbot/DarkGrey"/>
  </gazebo>
  <!-- front left wheel -->
  <gazebo reference="wheel_link_fl">
    <material value="youbot/Orange"/>
    <kp>1000000</kp>
    <kd>100</kd>
  </gazebo>
  <gazebo reference="caster_link_fl">
    <material value="youbot/Orange"/>
  </gazebo>
  <!-- front right wheel -->
  <gazebo reference="wheel_link_fr">
    <material value="youbot/Orange"/>
    <kp>1000000</kp>
    <kd>100</kd>
  </gazebo>
  <gazebo reference="caster_link_fr">
    <material value="youbot/Orange"/>
  </gazebo>
  <!-- back left wheel -->
  <gazebo reference="wheel_link_bl">
    <material value="youbot/Orange"/>
    <kp>1000000</kp>
    <kd>100</kd>
  </gazebo>
  <gazebo reference="caster_link_bl">
    <material value="youbot/Orange"/>
  </gazebo>
  <!-- back right wheel -->
  <gazebo reference="wheel_link_br">
    <material value="youbot/Orange"/>
    <kp>1000000</kp>
    <kd>100</kd>
  </gazebo>
  <gazebo reference="caster_link_br">
    <material value="youbot/Orange"/>
  </gazebo>
  <!-- position controller -->
  <gazebo>
    <plugin filename="libgazebo_ros_planar_move.so" name="base_controller">
      <commandTopic>cmd_vel</commandTopic>
      <odometryTopic>odom</odometryTopic>
      <odometryFrame>odom</odometryFrame>
      <odometryRate>100.0</odometryRate>
      <robotBaseFrame>ud_base_footprint</robotBaseFrame>
    </plugin>
  </gazebo>
  <!-- front left wheel -->
  <transmission name="wheel_trans_fl">
    <type>transmission_interface/SimpleTransmission</type>
    <actuator name="wheel_motor_fl">
      <hardwareInterface>VelocityJointInterface</hardwareInterface>
      <mechanicalReduction>79.2380952381</mechanicalReduction>
    </actuator>
    <joint name="wheel_joint_fl">
      <hardwareInterface>VelocityJointInterface</hardwareInterface>
    </joint>
  </transmission>
  <transmission name="caster_trans_fl">
    <type>transmission_interface/SimpleTransmission</type>
    <actuator name="caster_motor_fl">
      <hardwareInterface>VelocityJointInterface</hardwareInterface>
      <mechanicalReduction>79.2380952381</mechanicalReduction>
    </actuator>
    <joint name="caster_joint_fl">
      <hardwareInterface>VelocityJointInterface</hardwareInterface>
    </joint>
  </transmission>
  <!-- front right wheel -->
  <transmission name="wheel_trans_fr">
    <type>transmission_interface/SimpleTransmission</type>
    <actuator name="wheel_motor_fr">
      <hardwareInterface>VelocityJointInterface</hardwareInterface>
      <mechanicalReduction>79.2380952381</mechanicalReduction>
    </actuator>
    <joint name="wheel_joint_fr">
      <hardwareInterface>VelocityJointInterface</hardwareInterface>
    </joint>
  </transmission>
  <transmission name="caster_trans_fr">
    <type>transmission_interface/SimpleTransmission</type>
    <actuator name="caster_motor_fr">
      <hardwareInterface>VelocityJointInterface</hardwareInterface>
      <mechanicalReduction>79.2380952381</mechanicalReduction>
    </actuator>
    <joint name="caster_joint_fr">
      <hardwareInterface>VelocityJointInterface</hardwareInterface>
    </joint>
  </transmission>
  <!-- back left wheel -->
  <transmission name="wheel_trans_bl">
    <type>transmission_interface/SimpleTransmission</type>
    <actuator name="wheel_motor_bl">
      <hardwareInterface>VelocityJointInterface</hardwareInterface>
      <mechanicalReduction>79.2380952381</mechanicalReduction>
    </actuator>
    <joint name="wheel_joint_bl">
      <hardwareInterface>VelocityJointInterface</hardwareInterface>
    </joint>
  </transmission>
  <transmission name="caster_trans_bl">
    <type>transmission_interface/SimpleTransmission</type>
    <actuator name="caster_motor_bl">
      <hardwareInterface>VelocityJointInterface</hardwareInterface>
      <mechanicalReduction>79.2380952381</mechanicalReduction>
    </actuator>
    <joint name="caster_joint_bl">
      <hardwareInterface>VelocityJointInterface</hardwareInterface>
    </joint>
  </transmission>
  <!-- back right wheel -->
  <transmission name="wheel_trans_br">
    <type>transmission_interface/SimpleTransmission</type>
    <actuator name="wheel_motor_br">
      <hardwareInterface>VelocityJointInterface</hardwareInterface>
      <mechanicalReduction>79.2380952381</mechanicalReduction>
    </actuator>
    <joint name="wheel_joint_br">
      <hardwareInterface>VelocityJointInterface</hardwareInterface>
    </joint>
  </transmission>
  <transmission name="caster_trans_br">
    <type>transmission_interface/SimpleTransmission</type>
    <actuator name="caster_motor_br">
      <hardwareInterface>VelocityJointInterface</hardwareInterface>
      <mechanicalReduction>79.2380952381</mechanicalReduction>
    </actuator>
    <joint name="caster_joint_br">
      <hardwareInterface>VelocityJointInterface</hardwareInterface>
    </joint>
  </transmission>
  <joint name="ud_base_link_to_bottom_pillars_link" type="fixed">
    <origin rpy="0 0 0" xyz="0 0 0"/>
    <parent link="ud_base_link"/>
    <child link="bottom_pillars_link"/>
  </joint>
  <!-- joint for body and pantilt-->
  <joint name="top_plate_link_to_ud_pt_base_link" type="fixed">
    <origin rpy="0 0 0" xyz="0 0 0.0325 "/>
    <parent link="top_plate_link"/>
    <child link="ud_pt_base_link"/>
  </joint>
  <link name="kinect2_plate_link">
    <visual>
      <origin rpy="0 0 0" xyz="0 0 0"/>
      <geometry>
        <box size="0.25 0.015 0.01"/>
      </geometry>
      <material name="gray"/>
    </visual>
  </link>
  <joint name="ud_pt_projector_link_to_kinect2_plate_link" type="fixed">
    <origin rpy="0 0 3.14" xyz="0.075 -0.11 0.135"/>
    <parent link="ud_pt_projector_link"/>
    <child link="kinect2_plate_link"/>
  </joint>
  <link name="kinect2_rgb_optical_frame">
    <visual>
      <origin rpy="-1.56 0 0" xyz="0 0 0"/>
      <geometry>
        <!-- these meshes were exported in mm, so scale back to m -->
        <mesh filename="package://ubiquitous_display_description/meshes/kinect2_origin_on_rgb_optical_frame.stl" scale="0.001 0.001 0.001"/>
        <!--box size="0.25 0.07 0.45" /-->
      </geometry>
      <material name="black"/>
    </visual>
  </link>
  <link name="kinect2_ir_optical_frame">
    <visual>
      <origin rpy="0.075 0 0" xyz="0 0 0"/>
      <geometry>
        <sphere radius="0.0005"/>
      </geometry>
      <material name="black"/>
    </visual>
  </link>
  <joint name="kinect2_plate_to_kinect2_rgb_optical_frame" type="fixed">
    <origin rpy="0 0 0" xyz="0.095 0 0.035 "/>
    <parent link="kinect2_plate_link"/>
    <child link="kinect2_rgb_optical_frame"/>
  </joint>
  <joint name="kinect2_rgb_optical_frame_to_kinect2_ir_optical_frame" type="fixed">
    <origin rpy="0 0 0" xyz="-0.0425 0 0 "/>
    <parent link="kinect2_rgb_optical_frame"/>
    <child link="kinect2_ir_optical_frame"/>
  </joint>
  <joint name="front_laser_joint" type="fixed">
    <!--xacro:insert_block name="origin" /-->
    <origin rpy="0 0 0" xyz="-0.029 0 0.067"/>
    <parent link="front_laser_adjuster_link"/>
    <child link="front_laser_frame"/>
  </joint>
  <link name="front_laser_frame">
    <inertial>
      <mass value="0.270"/>
      <origin rpy="0 0 0" xyz="0 0 0"/>
      <inertia ixx="2.632e-4" ixy="0" ixz="0" iyy="2.632e-4" iyz="0" izz="1.62e-4"/>
    </inertial>
    <visual>
      <origin rpy="0 0 0" xyz="0 0 0"/>
      <geometry>
        <mesh filename="package://ubiquitous_display_description/meshes/hokuyo_utm_30lx.dae"/>
      </geometry>
    </visual>
    <collision>
      <origin rpy="0 0 0" xyz="0 0 -0.0115"/>
      <geometry>
        <box size="0.058 0.058 0.087"/>
        <!--<mesh filename="package://hector_sensors_description/meshes/hokuyo_utm30lx/hokuyo_utm_30lx.stl"/>-->
      </geometry>
    </collision>
  </link>
  <joint name="rear_laser_joint" type="fixed">
    <!--xacro:insert_block name="origin" /-->
    <origin rpy="0 0 0" xyz="-0.029 0 0.067"/>
    <parent link="rear_laser_adjuster_link"/>
    <child link="rear_laser_frame"/>
  </joint>
  <link name="rear_laser_frame">
    <inertial>
      <mass value="0.270"/>
      <origin rpy="0 0 0" xyz="0 0 0"/>
      <inertia ixx="2.632e-4" ixy="0" ixz="0" iyy="2.632e-4" iyz="0" izz="1.62e-4"/>
    </inertial>
    <visual>
      <origin rpy="0 0 0" xyz="0 0 0"/>
      <geometry>
        <mesh filename="package://ubiquitous_display_description/meshes/hokuyo_utm_30lx.dae"/>
      </geometry>
    </visual>
    <collision>
      <origin rpy="0 0 0" xyz="0 0 -0.0115"/>
      <geometry>
        <box size="0.058 0.058 0.087"/>
        <!--<mesh filename="package://hector_sensors_description/meshes/hokuyo_utm30lx/hokuyo_utm_30lx.stl"/>-->
      </geometry>
    </collision>
  </link>
  <!--xacro:kinect2_xacro prefix="ud" parent="kinect2_plate_link"/-->
</robot>
